const Pet = require('../database/models/Pet');
const Vaccination = require('../database/models/Vaccination');
const User = require('../database/models/User');

module.exports = {

  async index(req, res, next) {
    try {
      await Pet.findAll({ include: { association: 'tutor', exclude: ['senha'] } }).then(pets => {
        return res.status(200).json({ success: true, pets });
      }).catch(err => {
        res.status(400).json({
          success: false,
          message: 'Ocorreu um erro enquanto os dados eram recuperados.'
        });
      });
    } catch (error) {
      res.status(500).json({
        success: false,
        message: 'Ocorreu um erro desconhecido com o sistema.'
      });
    }
  },

  async store(req, res, next){

    const { ...new_pet } = req.body;

    try {
      await Pet.create(new_pet).then(pet => {
        return res.status(201).json({ success: true, pet });
      }).catch(err => {
        res.status(400).json({
          success: false,
          message: 'Ocorreu um erro enquanto os dados eram inseridos.'
        });
      });
    } catch (error) {
      res.status(500).json({
        success: false,
        message: 'Ocorreu um erro desconhecido com o sistema.'
      });
    }
  },

  async find(req, res, next) {
    const { id } = req.params

    try {
      await Pet.findByPk(id, { include: { association: 'tutor', exclude: ['senha'] } }).then(pet => {
        if(!pet) {
          return res.status(404).json({ success: false, message: 'O PET nÃ£o foi encontrado no sistema.' });
        }
        res.status(200).json({ success: true, pet });
      }).catch(() => {
        res.status(400).json({
            success: false,
            message: 'Ocorreu um erro enquanto os dados eram recuperados.'
        });
      })
    } catch (error) {
      res.status(500).json({
        success: false,
        message: 'Ocorreu um erro desconhecido com o sistema.'
      });
    }
  },

  async update(req, res, next) {
    const { id } = req.params;
    const { ...pet_update } = req.body;

    try {
      await Pet.update(pet_update, { where: { id } } ).then(rows_count => {
        Pet.findByPk(id).then(pet => {
          res.status(200).json({ success: true, pet });
        }).catch(erro => {
          res.status(400).json({
            success: false,
            message: 'Ocorreu um erro enquanto os dados eram recuperados.'
          });
        });
      }).catch(err => {
        res.status(400).json({
          success: false,
          message: 'Ocorreu um erro enquanto os dados eram atualizados.'
        });
      });
    } catch (error) {
      res.status(500).json({
        success: false,
        message: 'Ocorreu um erro desconhecido com o sistema.'
      });
    }
  },

  async delete(req, res, next) {
    const { id } = req.params;

    try {
      await Pet.findByPk(id).then(pet => {
        pet.destroy().then(pet2 => {
          res.status(200).json({
            success: true,
            message: 'Registro removido com sucesso.'
          });
        }).catch(() => {
          res.status(400).json({
            success: false,
            message: 'Ocorreu um erro enquanto os dados eram removidos.'
          });
        })
      }).catch(() => {
        res.status(400).json({
          success: false,
          message: 'Ocorreu um erro enquanto os dados eram recuperados.'
        });
      });
    } catch (error) {
      res.status(500).json({
        success: false,
        message: 'Ocorreu um erro desconhecido com o sistema.'
      });
    }
  },

  async findWithVaccinations(req, res, next) {
    const { id } = req.params;

    try {
      await Pet.findByPk(id, { 
        include: { 
          all: true
        }, 
        attributes: {
          exclude: ['senha'] 
        } 
      }).then(pet => {
        res.status(200).json({ success: true, pet });
      }).catch(err => {
        res.status(400).json({
          success: false,
          message: 'Ocorreu um erro enquanto os dados eram recuperados.'
        });
      });
    } catch (error) {
      res.status(500).json({
        success: false,
        message: 'Ocorreu um erro desconhecido com o sistema.'
      });
    }
  },

  async findVaccinated(req, res, next) {
    const has = req.query.has === "true";
    
    try {
      await Pet.findAll({ 
        include: [ 
          {model: Vaccination, as: 'vaccinations'},
          {model: User, as: 'tutor'},
        ] 
      }).then(pets => {
        var pets_vaccinated = [];
        var pets_not_vaccinated = [];
        
        pets.forEach(pet => {
          if (pet.vaccinations.length > 0) {
            pets_vaccinated.push(pet);
          } else {
            pets_not_vaccinated.push(pet);
          }
        });
        
        res.status(200).json({ 
          success: true, 
          pets: has ? pets_vaccinated : pets_not_vaccinated 
        });
      }).catch(err_find => {
        res.status(400).json({
          success: false,
          message: "Ocorreu um erro enquanto os dados eram recuperados."
        });
      });
    } catch (error) {
      res.status(500).json({
        success: false,
        message: 'Ocorreu um erro desconhecido com o sistema.'
      });
    }
  },

};
